Workbook
Name UpchargePct: Setup!$B$5
Name RoundInc: Setup!$B$6
Name Trucks: Setup!$A$11:$B$12
Name EquipRates: Setup!$A$16:$C$25
Name EquipNames: Setup!$A$16:$A$25
Name TechRates: Setup!$A$30:$D$37
Name TechCodes: Setup!$A$30:$A$37
Name ClientTable: Setup!$F$3:$I$8
Name ClientNames: Setup!$F$3:$F$8
Name CategoryList: Setup!$F$13:$F$20

Sheet Setup
A1: Setup — tarifas, técnicos y clientes | F1: Clientes
A2: Las celdas en crema son de entrada; las azules se calculan solas. | F2: Cliente | G2: Dirección | H2: Job / Descripción | I2: Términos
F3: Northgate Property Group | G3: 1420 W Main St, Springfield IL | H3: Time & materials service calls | I3: Net 15
A4: Parámetros
A5: Recargo sobre gastos (%) | B5: 0.15
A6: Incremento de redondeo (todo hacia arriba) | B6: 0.01
A7: Nombre de la empresa | B7: Your Company LLC
A9: Camiones
A10: Camión | B10: Tarifa por día
A11: Truck 1 | B11: 85 | F11: Categorías de cargo
A12: Truck 2 | B12: 45 | F12: Categoría | G12: Recargo 15%
F13: Truck 1 | G13: No
A14: Catálogo de equipos | F14: Truck 2 | G14: No
A15: Equipo | B15: Tarifa día completo | C15: Tarifa medio día | F15: Trip charge | G15: No
A16: Dump trailer | B16: 150 | C16: 90 | F16: Equipment | G16: No
A17: Utility trailer | B17: 60 | C17: 35 | F17: Truck stock | G17: Yes
A18: Tractor | B18: 250 | C18: 150 | F18: Purchase | G18: Yes
A19: Tractor implement | B19: 75 | C19: 40 | F19: Tech expense | G19: Yes
A20: Mini excavator | B20: 400 | C20: 250 | F20: Other | G20: Yes
A21: Compressor | B21: 60 | C21: 35
A22: Generator | B22: 55 | C22: 30
A28: Técnicos
A29: Código | B29: Nombre | C29: Tarifa facturada/h | D29: Tarifa a pagar/h
A30: Tech 1 | B30: Tech 1 | C30: 65 | D30: 35
A31: Tech 2 | B31: Tech 2 | C31: 55 | D31: 30
A32: Tech 3 | B32: Tech 3 | C32: 48 | D32: 26
A33: Tech 4 | B33: Tech 4 | C33: 42 | D33: 22
A34: Tech 5 | B34: Tech 5 | C34: 38 | D34: 20
A35: Tech 6 | B35: Tech 6 | C35: 35 | D35: 18
A36: Tech 7 | B36: Tech 7 | C36: 0 | D36: 0
A37: Tech 8 | B37: Tech 8 | C37: 0 | D37: 0

Sheet Labor
A1: Date | B1: Day | C1: Tech | D1: Hours | E1: Billed rate | F1: Labor total | G1: Note | H1: DaySeq | I1: LookupKey
B2: =IF($A2="","",TEXT($A2,"ddd")) | E2: =IF($C2="","",IFERROR(VLOOKUP($C2,TechRates,3,FALSE),0)) | F2: =IF(OR($A2="",$D2=""),"",CEILING($D2*$E2,RoundInc)) | H2: =IF($A2="","",COUNTIF($A$2:$A2,$A2)) | I2: =IF($A2="","",TEXT($A2,"yyyy-mm-dd")&"#"&$H2)
B3: =IF($A3="","",TEXT($A3,"ddd")) | E3: =IF($C3="","",IFERROR(VLOOKUP($C3,TechRates,3,FALSE),0)) | F3: =IF(OR($A3="",$D3=""),"",CEILING($D3*$E3,RoundInc)) | H3: =IF($A3="","",COUNTIF($A$2:$A3,$A3)) | I3: =IF($A3="","",TEXT($A3,"yyyy-mm-dd")&"#"&$H3)
B4: =IF($A4="","",TEXT($A4,"ddd")) | E4: =IF($C4="","",IFERROR(VLOOKUP($C4,TechRates,3,FALSE),0)) | F4: =IF(OR($A4="",$D4=""),"",CEILING($D4*$E4,RoundInc)) | H4: =IF($A4="","",COUNTIF($A$2:$A4,$A4)) | I4: =IF($A4="","",TEXT($A4,"yyyy-mm-dd")&"#"&$H4)
B5: =IF($A5="","",TEXT($A5,"ddd")) | E5: =IF($C5="","",IFERROR(VLOOKUP($C5,TechRates,3,FALSE),0)) | F5: =IF(OR($A5="",$D5=""),"",CEILING($D5*$E5,RoundInc)) | H5: =IF($A5="","",COUNTIF($A$2:$A5,$A5)) | I5: =IF($A5="","",TEXT($A5,"yyyy-mm-dd")&"#"&$H5)
B6: =IF($A6="","",TEXT($A6,"ddd")) | E6: =IF($C6="","",IFERROR(VLOOKUP($C6,TechRates,3,FALSE),0)) | F6: =IF(OR($A6="",$D6=""),"",CEILING($D6*$E6,RoundInc)) | H6: =IF($A6="","",COUNTIF($A$2:$A6,$A6)) | I6: =IF($A6="","",TEXT($A6,"yyyy-mm-dd")&"#"&$H6)
B7: =IF($A7="","",TEXT($A7,"ddd")) | E7: =IF($C7="","",IFERROR(VLOOKUP($C7,TechRates,3,FALSE),0)) | F7: =IF(OR($A7="",$D7=""),"",CEILING($D7*$E7,RoundInc)) | H7: =IF($A7="","",COUNTIF($A$2:$A7,$A7)) | I7: =IF($A7="","",TEXT($A7,"yyyy-mm-dd")&"#"&$H7)
B8: =IF($A8="","",TEXT($A8,"ddd")) | E8: =IF($C8="","",IFERROR(VLOOKUP($C8,TechRates,3,FALSE),0)) | F8: =IF(OR($A8="",$D8=""),"",CEILING($D8*$E8,RoundInc)) | H8: =IF($A8="","",COUNTIF($A$2:$A8,$A8)) | I8: =IF($A8="","",TEXT($A8,"yyyy-mm-dd")&"#"&$H8)
B9: =IF($A9="","",TEXT($A9,"ddd")) | E9: =IF($C9="","",IFERROR(VLOOKUP($C9,TechRates,3,FALSE),0)) | F9: =IF(OR($A9="",$D9=""),"",CEILING($D9*$E9,RoundInc)) | H9: =IF($A9="","",COUNTIF($A$2:$A9,$A9)) | I9: =IF($A9="","",TEXT($A9,"yyyy-mm-dd")&"#"&$H9)
B10: =IF($A10="","",TEXT($A10,"ddd")) | E10: =IF($C10="","",IFERROR(VLOOKUP($C10,TechRates,3,FALSE),0)) | F10: =IF(OR($A10="",$D10=""),"",CEILING($D10*$E10,RoundInc)) | H10: =IF($A10="","",COUNTIF($A$2:$A10,$A10)) | I10: =IF($A10="","",TEXT($A10,"yyyy-mm-dd")&"#"&$H10)
B11: =IF($A11="","",TEXT($A11,"ddd")) | E11: =IF($C11="","",IFERROR(VLOOKUP($C11,TechRates,3,FALSE),0)) | F11: =IF(OR($A11="",$D11=""),"",CEILING($D11*$E11,RoundInc)) | H11: =IF($A11="","",COUNTIF($A$2:$A11,$A11)) | I11: =IF($A11="","",TEXT($A11,"yyyy-mm-dd")&"#"&$H11)
B12: =IF($A12="","",TEXT($A12,"ddd")) | E12: =IF($C12="","",IFERROR(VLOOKUP($C12,TechRates,3,FALSE),0)) | F12: =IF(OR($A12="",$D12=""),"",CEILING($D12*$E12,RoundInc)) | H12: =IF($A12="","",COUNTIF($A$2:$A12,$A12)) | I12: =IF($A12="","",TEXT($A12,"yyyy-mm-dd")&"#"&$H12)
B13: =IF($A13="","",TEXT($A13,"ddd")) | E13: =IF($C13="","",IFERROR(VLOOKUP($C13,TechRates,3,FALSE),0)) | F13: =IF(OR($A13="",$D13=""),"",CEILING($D13*$E13,RoundInc)) | H13: =IF($A13="","",COUNTIF($A$2:$A13,$A13)) | I13: =IF($A13="","",TEXT($A13,"yyyy-mm-dd")&"#"&$H13)
... B301: =IF($A301="","",TEXT($A301,"ddd")) | E301: =IF($C301="","",IFERROR(VLOOKUP($C301,TechRates,3,FALSE),0)) | F301: =IF(OR($A301="",$D301=""),"",CEILING($D301*$E301,RoundInc)) | H301: =IF($A301="","",COUNTIF($A$2:$A301,$A301)) | I301: =IF($A301="","",TEXT($A301,"yyyy-mm-dd")&"#"&$H301)

Sheet Charges
A1: Date | B1: Day | C1: Category | D1: Tech | E1: Item / Description | F1: Units | G1: Amount (override) | H1: Rate / Unit | I1: Charge | J1: Billable | K1: Markup 15% | L1: Reimburse tech | M1: DaySeq | N1: LookupKey
B2: =IF($A2="","",TEXT($A2,"ddd")) | H2: =IF($C2="","",IF($C2="Equipment",IFERROR(VLOOKUP($E2,EquipRates,IF(AND($F2<>"",$F2<1),3,2),FALSE),0),IFERROR(VLOOKUP($C2,Trucks,2,FALSE),""))) | I2: =IF($C2="","",CEILING(IF($H2<>"",$H2,IF($G2="",0,$G2))*IF($F2="",1,$F2),RoundInc)) | K2: =IF($C2="","",IF(OR($C2="Truck stock",$C2="Purchase",$C2="Tech expense",$C2="Other"),"Yes","No")) | M2: =IF($A2="","",COUNTIF($A$2:$A2,$A2)) | N2: =IF($A2="","",TEXT($A2,"yyyy-mm-dd")&"#"&$M2)
B3: =IF($A3="","",TEXT($A3,"ddd")) | H3: =IF($C3="","",IF($C3="Equipment",IFERROR(VLOOKUP($E3,EquipRates,IF(AND($F3<>"",$F3<1),3,2),FALSE),0),IFERROR(VLOOKUP($C3,Trucks,2,FALSE),""))) | I3: =IF($C3="","",CEILING(IF($H3<>"",$H3,IF($G3="",0,$G3))*IF($F3="",1,$F3),RoundInc)) | K3: =IF($C3="","",IF(OR($C3="Truck stock",$C3="Purchase",$C3="Tech expense",$C3="Other"),"Yes","No")) | M3: =IF($A3="","",COUNTIF($A$2:$A3,$A3)) | N3: =IF($A3="","",TEXT($A3,"yyyy-mm-dd")&"#"&$M3)
B4: =IF($A4="","",TEXT($A4,"ddd")) | H4: =IF($C4="","",IF($C4="Equipment",IFERROR(VLOOKUP($E4,EquipRates,IF(AND($F4<>"",$F4<1),3,2),FALSE),0),IFERROR(VLOOKUP($C4,Trucks,2,FALSE),""))) | I4: =IF($C4="","",CEILING(IF($H4<>"",$H4,IF($G4="",0,$G4))*IF($F4="",1,$F4),RoundInc)) | K4: =IF($C4="","",IF(OR($C4="Truck stock",$C4="Purchase",$C4="Tech expense",$C4="Other"),"Yes","No")) | M4: =IF($A4="","",COUNTIF($A$2:$A4,$A4)) | N4: =IF($A4="","",TEXT($A4,"yyyy-mm-dd")&"#"&$M4)
B5: =IF($A5="","",TEXT($A5,"ddd")) | H5: =IF($C5="","",IF($C5="Equipment",IFERROR(VLOOKUP($E5,EquipRates,IF(AND($F5<>"",$F5<1),3,2),FALSE),0),IFERROR(VLOOKUP($C5,Trucks,2,FALSE),""))) | I5: =IF($C5="","",CEILING(IF($H5<>"",$H5,IF($G5="",0,$G5))*IF($F5="",1,$F5),RoundInc)) | K5: =IF($C5="","",IF(OR($C5="Truck stock",$C5="Purchase",$C5="Tech expense",$C5="Other"),"Yes","No")) | M5: =IF($A5="","",COUNTIF($A$2:$A5,$A5)) | N5: =IF($A5="","",TEXT($A5,"yyyy-mm-dd")&"#"&$M5)
B6: =IF($A6="","",TEXT($A6,"ddd")) | H6: =IF($C6="","",IF($C6="Equipment",IFERROR(VLOOKUP($E6,EquipRates,IF(AND($F6<>"",$F6<1),3,2),FALSE),0),IFERROR(VLOOKUP($C6,Trucks,2,FALSE),""))) | I6: =IF($C6="","",CEILING(IF($H6<>"",$H6,IF($G6="",0,$G6))*IF($F6="",1,$F6),RoundInc)) | K6: =IF($C6="","",IF(OR($C6="Truck stock",$C6="Purchase",$C6="Tech expense",$C6="Other"),"Yes","No")) | M6: =IF($A6="","",COUNTIF($A$2:$A6,$A6)) | N6: =IF($A6="","",TEXT($A6,"yyyy-mm-dd")&"#"&$M6)
B7: =IF($A7="","",TEXT($A7,"ddd")) | H7: =IF($C7="","",IF($C7="Equipment",IFERROR(VLOOKUP($E7,EquipRates,IF(AND($F7<>"",$F7<1),3,2),FALSE),0),IFERROR(VLOOKUP($C7,Trucks,2,FALSE),""))) | I7: =IF($C7="","",CEILING(IF($H7<>"",$H7,IF($G7="",0,$G7))*IF($F7="",1,$F7),RoundInc)) | K7: =IF($C7="","",IF(OR($C7="Truck stock",$C7="Purchase",$C7="Tech expense",$C7="Other"),"Yes","No")) | M7: =IF($A7="","",COUNTIF($A$2:$A7,$A7)) | N7: =IF($A7="","",TEXT($A7,"yyyy-mm-dd")&"#"&$M7)
B8: =IF($A8="","",TEXT($A8,"ddd")) | H8: =IF($C8="","",IF($C8="Equipment",IFERROR(VLOOKUP($E8,EquipRates,IF(AND($F8<>"",$F8<1),3,2),FALSE),0),IFERROR(VLOOKUP($C8,Trucks,2,FALSE),""))) | I8: =IF($C8="","",CEILING(IF($H8<>"",$H8,IF($G8="",0,$G8))*IF($F8="",1,$F8),RoundInc)) | K8: =IF($C8="","",IF(OR($C8="Truck stock",$C8="Purchase",$C8="Tech expense",$C8="Other"),"Yes","No")) | M8: =IF($A8="","",COUNTIF($A$2:$A8,$A8)) | N8: =IF($A8="","",TEXT($A8,"yyyy-mm-dd")&"#"&$M8)
B9: =IF($A9="","",TEXT($A9,"ddd")) | H9: =IF($C9="","",IF($C9="Equipment",IFERROR(VLOOKUP($E9,EquipRates,IF(AND($F9<>"",$F9<1),3,2),FALSE),0),IFERROR(VLOOKUP($C9,Trucks,2,FALSE),""))) | I9: =IF($C9="","",CEILING(IF($H9<>"",$H9,IF($G9="",0,$G9))*IF($F9="",1,$F9),RoundInc)) | K9: =IF($C9="","",IF(OR($C9="Truck stock",$C9="Purchase",$C9="Tech expense",$C9="Other"),"Yes","No")) | M9: =IF($A9="","",COUNTIF($A$2:$A9,$A9)) | N9: =IF($A9="","",TEXT($A9,"yyyy-mm-dd")&"#"&$M9)
B10: =IF($A10="","",TEXT($A10,"ddd")) | H10: =IF($C10="","",IF($C10="Equipment",IFERROR(VLOOKUP($E10,EquipRates,IF(AND($F10<>"",$F10<1),3,2),FALSE),0),IFERROR(VLOOKUP($C10,Trucks,2,FALSE),""))) | I10: =IF($C10="","",CEILING(IF($H10<>"",$H10,IF($G10="",0,$G10))*IF($F10="",1,$F10),RoundInc)) | K10: =IF($C10="","",IF(OR($C10="Truck stock",$C10="Purchase",$C10="Tech expense",$C10="Other"),"Yes","No")) | M10: =IF($A10="","",COUNTIF($A$2:$A10,$A10)) | N10: =IF($A10="","",TEXT($A10,"yyyy-mm-dd")&"#"&$M10)
B11: =IF($A11="","",TEXT($A11,"ddd")) | H11: =IF($C11="","",IF($C11="Equipment",IFERROR(VLOOKUP($E11,EquipRates,IF(AND($F11<>"",$F11<1),3,2),FALSE),0),IFERROR(VLOOKUP($C11,Trucks,2,FALSE),""))) | I11: =IF($C11="","",CEILING(IF($H11<>"",$H11,IF($G11="",0,$G11))*IF($F11="",1,$F11),RoundInc)) | K11: =IF($C11="","",IF(OR($C11="Truck stock",$C11="Purchase",$C11="Tech expense",$C11="Other"),"Yes","No")) | M11: =IF($A11="","",COUNTIF($A$2:$A11,$A11)) | N11: =IF($A11="","",TEXT($A11,"yyyy-mm-dd")&"#"&$M11)
B12: =IF($A12="","",TEXT($A12,"ddd")) | H12: =IF($C12="","",IF($C12="Equipment",IFERROR(VLOOKUP($E12,EquipRates,IF(AND($F12<>"",$F12<1),3,2),FALSE),0),IFERROR(VLOOKUP($C12,Trucks,2,FALSE),""))) | I12: =IF($C12="","",CEILING(IF($H12<>"",$H12,IF($G12="",0,$G12))*IF($F12="",1,$F12),RoundInc)) | K12: =IF($C12="","",IF(OR($C12="Truck stock",$C12="Purchase",$C12="Tech expense",$C12="Other"),"Yes","No")) | M12: =IF($A12="","",COUNTIF($A$2:$A12,$A12)) | N12: =IF($A12="","",TEXT($A12,"yyyy-mm-dd")&"#"&$M12)
B13: =IF($A13="","",TEXT($A13,"ddd")) | H13: =IF($C13="","",IF($C13="Equipment",IFERROR(VLOOKUP($E13,EquipRates,IF(AND($F13<>"",$F13<1),3,2),FALSE),0),IFERROR(VLOOKUP($C13,Trucks,2,FALSE),""))) | I13: =IF($C13="","",CEILING(IF($H13<>"",$H13,IF($G13="",0,$G13))*IF($F13="",1,$F13),RoundInc)) | K13: =IF($C13="","",IF(OR($C13="Truck stock",$C13="Purchase",$C13="Tech expense",$C13="Other"),"Yes","No")) | M13: =IF($A13="","",COUNTIF($A$2:$A13,$A13)) | N13: =IF($A13="","",TEXT($A13,"yyyy-mm-dd")&"#"&$M13)
... B302: =IF($A302="","",TEXT($A302,"ddd")) | H302: =IF($C302="","",IF($C302="Equipment",IFERROR(VLOOKUP($E302,EquipRates,IF(AND($F302<>"",$F302<1),3,2),FALSE),0),IFERROR(VLOOKUP($C302,Trucks,2,FALSE),""))) | I302: =IF($C302="","",CEILING(IF($H302<>"",$H302,IF($G302="",0,$G302))*IF($F302="",1,$F302),RoundInc)) | K302: =IF($C302="","",IF(OR($C302="Truck stock",$C302="Purchase",$C302="Tech expense",$C302="Other"),"Yes","No")) | M302: =IF($A302="","",COUNTIF($A$2:$A302,$A302)) | N302: =IF($A302="","",TEXT($A302,"yyyy-mm-dd")&"#"&$M302)

Sheet Invoice
A1: Invoice — Summary accounting sheet
A2: Elige cliente y rango de fechas. Todo lo demás se calcula solo.
A4: Client
A5: From date
A6: To date
A7: Discount (%) | B7: 0
A8: Discount ($ flat) | B8: 0
A10: Company | B10: =Setup!$B$7
A11: Bill to | B11: =IFERROR(IF($B$4="","",VLOOKUP($B$4,ClientTable,1,FALSE)),"")
A12: Address | B12: =IFERROR(IF($B$4="","",VLOOKUP($B$4,ClientTable,2,FALSE)),"")
A13: Job / Description | B13: =IFERROR(IF($B$4="","",VLOOKUP($B$4,ClientTable,3,FALSE)),"")
A14: Terms | B14: =IFERROR(IF($B$4="","",VLOOKUP($B$4,ClientTable,4,FALSE)),"")
A17: Labor — tech | B17: Hours | C17: Billed rate | D17: Amount
A18: =Setup!$A$30 | B18: =SUMIFS(Labor!$D$2:$D$301,Labor!$C$2:$C$301,$A18,Labor!$A$2:$A$301,">="&$B$5,Labor!$A$2:$A$301,"<="&$B$6) | C18: =IFERROR(VLOOKUP($A18,TechRates,3,FALSE),0) | D18: =CEILING($B18*$C18,RoundInc)
A19: =Setup!$A$31 | B19: =SUMIFS(Labor!$D$2:$D$301,Labor!$C$2:$C$301,$A19,Labor!$A$2:$A$301,">="&$B$5,Labor!$A$2:$A$301,"<="&$B$6) | C19: =IFERROR(VLOOKUP($A19,TechRates,3,FALSE),0) | D19: =CEILING($B19*$C19,RoundInc)
A20: =Setup!$A$32 | B20: =SUMIFS(Labor!$D$2:$D$301,Labor!$C$2:$C$301,$A20,Labor!$A$2:$A$301,">="&$B$5,Labor!$A$2:$A$301,"<="&$B$6) | C20: =IFERROR(VLOOKUP($A20,TechRates,3,FALSE),0) | D20: =CEILING($B20*$C20,RoundInc)
A21: =Setup!$A$33 | B21: =SUMIFS(Labor!$D$2:$D$301,Labor!$C$2:$C$301,$A21,Labor!$A$2:$A$301,">="&$B$5,Labor!$A$2:$A$301,"<="&$B$6) | C21: =IFERROR(VLOOKUP($A21,TechRates,3,FALSE),0) | D21: =CEILING($B21*$C21,RoundInc)
A22: =Setup!$A$34 | B22: =SUMIFS(Labor!$D$2:$D$301,Labor!$C$2:$C$301,$A22,Labor!$A$2:$A$301,">="&$B$5,Labor!$A$2:$A$301,"<="&$B$6) | C22: =IFERROR(VLOOKUP($A22,TechRates,3,FALSE),0) | D22: =CEILING($B22*$C22,RoundInc)
A23: =Setup!$A$35 | B23: =SUMIFS(Labor!$D$2:$D$301,Labor!$C$2:$C$301,$A23,Labor!$A$2:$A$301,">="&$B$5,Labor!$A$2:$A$301,"<="&$B$6) | C23: =IFERROR(VLOOKUP($A23,TechRates,3,FALSE),0) | D23: =CEILING($B23*$C23,RoundInc)
A24: =Setup!$A$36 | B24: =SUMIFS(Labor!$D$2:$D$301,Labor!$C$2:$C$301,$A24,Labor!$A$2:$A$301,">="&$B$5,Labor!$A$2:$A$301,"<="&$B$6) | C24: =IFERROR(VLOOKUP($A24,TechRates,3,FALSE),0) | D24: =CEILING($B24*$C24,RoundInc)
A25: =Setup!$A$37 | B25: =SUMIFS(Labor!$D$2:$D$301,Labor!$C$2:$C$301,$A25,Labor!$A$2:$A$301,">="&$B$5,Labor!$A$2:$A$301,"<="&$B$6) | C25: =IFERROR(VLOOKUP($A25,TechRates,3,FALSE),0) | D25: =CEILING($B25*$C25,RoundInc)
C26: Labor subtotal | D26: =CEILING(SUM(D18:D25),RoundInc)
A28: Charges — no markup | D28: Amount
A29: Truck 1 | D29: =SUMIFS(Charges!$I$2:$I$301,Charges!$C$2:$C$301,$A29,Charges!$J$2:$J$301,"Yes",Charges!$A$2:$A$301,">="&$B$5,Charges!$A$2:$A$301,"<="&$B$6)
A30: Truck 2 | D30: =SUMIFS(Charges!$I$2:$I$301,Charges!$C$2:$C$301,$A30,Charges!$J$2:$J$301,"Yes",Charges!$A$2:$A$301,">="&$B$5,Charges!$A$2:$A$301,"<="&$B$6)
A31: Trip charge | D31: =SUMIFS(Charges!$I$2:$I$301,Charges!$C$2:$C$301,$A31,Charges!$J$2:$J$301,"Yes",Charges!$A$2:$A$301,">="&$B$5,Charges!$A$2:$A$301,"<="&$B$6)
A32: Equipment | D32: =SUMIFS(Charges!$I$2:$I$301,Charges!$C$2:$C$301,$A32,Charges!$J$2:$J$301,"Yes",Charges!$A$2:$A$301,">="&$B$5,Charges!$A$2:$A$301,"<="&$B$6)
C33: Trucks / equipment subtotal | D33: =CEILING(SUM(D29:D32),RoundInc)
A35: Expenses (markup applies) | D35: Amount
A36: Truck stock | D36: =SUMIFS(Charges!$I$2:$I$301,Charges!$C$2:$C$301,$A36,Charges!$J$2:$J$301,"Yes",Charges!$A$2:$A$301,">="&$B$5,Charges!$A$2:$A$301,"<="&$B$6)
A37: Purchase | D37: =SUMIFS(Charges!$I$2:$I$301,Charges!$C$2:$C$301,$A37,Charges!$J$2:$J$301,"Yes",Charges!$A$2:$A$301,">="&$B$5,Charges!$A$2:$A$301,"<="&$B$6)
A38: Tech expense | D38: =SUMIFS(Charges!$I$2:$I$301,Charges!$C$2:$C$301,$A38,Charges!$J$2:$J$301,"Yes",Charges!$A$2:$A$301,">="&$B$5,Charges!$A$2:$A$301,"<="&$B$6)
A39: Other | D39: =SUMIFS(Charges!$I$2:$I$301,Charges!$C$2:$C$301,$A39,Charges!$J$2:$J$301,"Yes",Charges!$A$2:$A$301,">="&$B$5,Charges!$A$2:$A$301,"<="&$B$6)
C40: Expenses subtotal | D40: =CEILING(SUM(D36:D39),RoundInc)
C41: Expense upcharge 15% | D41: =CEILING(D40*UpchargePct,RoundInc)
C42: Expenses with upcharge | D42: =CEILING(D40+D41,RoundInc)
C44: Subtotal | D44: =CEILING(D26+D33+D42,RoundInc)
C45: Discount (%) | D45: =CEILING(D44*$B$7,RoundInc)
C46: Discount ($ flat) | D46: =$B$8
C47: Total discount | D47: =CEILING(D45+D46,RoundInc)
...

Sheet Payroll
A1: Payroll — nómina por técnico
A2: Elige el rango de fechas: la nómina se calcula sobre las horas registradas.
A4: From date
A5: To date
A7: Tech | B7: Name | C7: Hours | D7: Pay rate | E7: Gross pay | F7: Reimbursements | G7: Total to pay
A8: =Setup!$A$30 | B8: =IFERROR(VLOOKUP($A8,TechRates,2,FALSE),"") | C8: =SUMIFS(Labor!$D$2:$D$301,Labor!$C$2:$C$301,$A8,Labor!$A$2:$A$301,">="&$B$4,Labor!$A$2:$A$301,"<="&$B$5) | D8: =IFERROR(VLOOKUP($A8,TechRates,4,FALSE),0) | E8: =CEILING($C8*$D8,RoundInc) | F8: =SUMIFS(Charges!$I$2:$I$301,Charges!$D$2:$D$301,$A8,Charges!$C$2:$C$301,"Tech expense",Charges!$L$2:$L$301,"Yes",Charges!$A$2:$A$301,">="&$B$4,Charges!$A$2:$A$301,"<="&$B$5) | G8: =CEILING($E8+$F8,RoundInc)
A9: =Setup!$A$31 | B9: =IFERROR(VLOOKUP($A9,TechRates,2,FALSE),"") | C9: =SUMIFS(Labor!$D$2:$D$301,Labor!$C$2:$C$301,$A9,Labor!$A$2:$A$301,">="&$B$4,Labor!$A$2:$A$301,"<="&$B$5) | D9: =IFERROR(VLOOKUP($A9,TechRates,4,FALSE),0) | E9: =CEILING($C9*$D9,RoundInc) | F9: =SUMIFS(Charges!$I$2:$I$301,Charges!$D$2:$D$301,$A9,Charges!$C$2:$C$301,"Tech expense",Charges!$L$2:$L$301,"Yes",Charges!$A$2:$A$301,">="&$B$4,Charges!$A$2:$A$301,"<="&$B$5) | G9: =CEILING($E9+$F9,RoundInc)
A10: =Setup!$A$32 | B10: =IFERROR(VLOOKUP($A10,TechRates,2,FALSE),"") | C10: =SUMIFS(Labor!$D$2:$D$301,Labor!$C$2:$C$301,$A10,Labor!$A$2:$A$301,">="&$B$4,Labor!$A$2:$A$301,"<="&$B$5) | D10: =IFERROR(VLOOKUP($A10,TechRates,4,FALSE),0) | E10: =CEILING($C10*$D10,RoundInc) | F10: =SUMIFS(Charges!$I$2:$I$301,Charges!$D$2:$D$301,$A10,Charges!$C$2:$C$301,"Tech expense",Charges!$L$2:$L$301,"Yes",Charges!$A$2:$A$301,">="&$B$4,Charges!$A$2:$A$301,"<="&$B$5) | G10: =CEILING($E10+$F10,RoundInc)
A11: =Setup!$A$33 | B11: =IFERROR(VLOOKUP($A11,TechRates,2,FALSE),"") | C11: =SUMIFS(Labor!$D$2:$D$301,Labor!$C$2:$C$301,$A11,Labor!$A$2:$A$301,">="&$B$4,Labor!$A$2:$A$301,"<="&$B$5) | D11: =IFERROR(VLOOKUP($A11,TechRates,4,FALSE),0) | E11: =CEILING($C11*$D11,RoundInc) | F11: =SUMIFS(Charges!$I$2:$I$301,Charges!$D$2:$D$301,$A11,Charges!$C$2:$C$301,"Tech expense",Charges!$L$2:$L$301,"Yes",Charges!$A$2:$A$301,">="&$B$4,Charges!$A$2:$A$301,"<="&$B$5) | G11: =CEILING($E11+$F11,RoundInc)
A12: =Setup!$A$34 | B12: =IFERROR(VLOOKUP($A12,TechRates,2,FALSE),"") | C12: =SUMIFS(Labor!$D$2:$D$301,Labor!$C$2:$C$301,$A12,Labor!$A$2:$A$301,">="&$B$4,Labor!$A$2:$A$301,"<="&$B$5) | D12: =IFERROR(VLOOKUP($A12,TechRates,4,FALSE),0) | E12: =CEILING($C12*$D12,RoundInc) | F12: =SUMIFS(Charges!$I$2:$I$301,Charges!$D$2:$D$301,$A12,Charges!$C$2:$C$301,"Tech expense",Charges!$L$2:$L$301,"Yes",Charges!$A$2:$A$301,">="&$B$4,Charges!$A$2:$A$301,"<="&$B$5) | G12: =CEILING($E12+$F12,RoundInc)
A13: =Setup!$A$35 | B13: =IFERROR(VLOOKUP($A13,TechRates,2,FALSE),"") | C13: =SUMIFS(Labor!$D$2:$D$301,Labor!$C$2:$C$301,$A13,Labor!$A$2:$A$301,">="&$B$4,Labor!$A$2:$A$301,"<="&$B$5) | D13: =IFERROR(VLOOKUP($A13,TechRates,4,FALSE),0) | E13: =CEILING($C13*$D13,RoundInc) | F13: =SUMIFS(Charges!$I$2:$I$301,Charges!$D$2:$D$301,$A13,Charges!$C$2:$C$301,"Tech expense",Charges!$L$2:$L$301,"Yes",Charges!$A$2:$A$301,">="&$B$4,Charges!$A$2:$A$301,"<="&$B$5) | G13: =CEILING($E13+$F13,RoundInc)
A14: =Setup!$A$36 | B14: =IFERROR(VLOOKUP($A14,TechRates,2,FALSE),"") | C14: =SUMIFS(Labor!$D$2:$D$301,Labor!$C$2:$C$301,$A14,Labor!$A$2:$A$301,">="&$B$4,Labor!$A$2:$A$301,"<="&$B$5) | D14: =IFERROR(VLOOKUP($A14,TechRates,4,FALSE),0) | E14: =CEILING($C14*$D14,RoundInc) | F14: =SUMIFS(Charges!$I$2:$I$301,Charges!$D$2:$D$301,$A14,Charges!$C$2:$C$301,"Tech expense",Charges!$L$2:$L$301,"Yes",Charges!$A$2:$A$301,">="&$B$4,Charges!$A$2:$A$301,"<="&$B$5) | G14: =CEILING($E14+$F14,RoundInc)
A15: =Setup!$A$37 | B15: =IFERROR(VLOOKUP($A15,TechRates,2,FALSE),"") | C15: =SUMIFS(Labor!$D$2:$D$301,Labor!$C$2:$C$301,$A15,Labor!$A$2:$A$301,">="&$B$4,Labor!$A$2:$A$301,"<="&$B$5) | D15: =IFERROR(VLOOKUP($A15,TechRates,4,FALSE),0) | E15: =CEILING($C15*$D15,RoundInc) | F15: =SUMIFS(Charges!$I$2:$I$301,Charges!$D$2:$D$301,$A15,Charges!$C$2:$C$301,"Tech expense",Charges!$L$2:$L$301,"Yes",Charges!$A$2:$A$301,">="&$B$4,Charges!$A$2:$A$301,"<="&$B$5) | G15: =CEILING($E15+$F15,RoundInc)
B16: TOTAL PAYROLL | C16: =CEILING(SUM(C8:C15),RoundInc) | E16: =CEILING(SUM(E8:E15),RoundInc) | F16: =CEILING(SUM(F8:F15),RoundInc) | G16: =CEILING(SUM(G8:G15),RoundInc)
A18: Reimbursements = cargos de categoría "Tech expense" con "Reimburse tech" = Yes en la hoja Charges.

Sheet DailySheet
A1: Daily accounting sheet — entregable al cliente
A2: Escribe la fecha arriba (G3). El detalle del día se rellena solo.
G3: Date shown | H3: =Invoice!$B$5
A4: Client | B4: =IFERROR(VLOOKUP(Invoice!$B$4,ClientTable,1,FALSE),"")
A5: Address | B5: =IFERROR(VLOOKUP(Invoice!$B$4,ClientTable,2,FALSE),"")
A6: Job / Description | B6: =IFERROR(VLOOKUP(Invoice!$B$4,ClientTable,3,FALSE),"")
A7: Date | B7: =Invoice!$B$5
A9: Labor | B9: Tech | C9: Hours | D9: Rate | E9: Amount
B10: =IFERROR(INDEX(Labor!$C$2:$C$301,MATCH(TEXT($H$3,"yyyy-mm-dd")&"#"&1,Labor!$I$2:$I$301,0)),"") | C10: =IFERROR(INDEX(Labor!$D$2:$D$301,MATCH(TEXT($H$3,"yyyy-mm-dd")&"#"&1,Labor!$I$2:$I$301,0)),"") | D10: =IFERROR(INDEX(Labor!$E$2:$E$301,MATCH(TEXT($H$3,"yyyy-mm-dd")&"#"&1,Labor!$I$2:$I$301,0)),"") | E10: =IFERROR(INDEX(Labor!$F$2:$F$301,MATCH(TEXT($H$3,"yyyy-mm-dd")&"#"&1,Labor!$I$2:$I$301,0)),"")
B11: =IFERROR(INDEX(Labor!$C$2:$C$301,MATCH(TEXT($H$3,"yyyy-mm-dd")&"#"&2,Labor!$I$2:$I$301,0)),"") | C11: =IFERROR(INDEX(Labor!$D$2:$D$301,MATCH(TEXT($H$3,"yyyy-mm-dd")&"#"&2,Labor!$I$2:$I$301,0)),"") | D11: =IFERROR(INDEX(Labor!$E$2:$E$301,MATCH(TEXT($H$3,"yyyy-mm-dd")&"#"&2,Labor!$I$2:$I$301,0)),"") | E11: =IFERROR(INDEX(Labor!$F$2:$F$301,MATCH(TEXT($H$3,"yyyy-mm-dd")&"#"&2,Labor!$I$2:$I$301,0)),"")
B12: =IFERROR(INDEX(Labor!$C$2:$C$301,MATCH(TEXT($H$3,"yyyy-mm-dd")&"#"&3,Labor!$I$2:$I$301,0)),"") | C12: =IFERROR(INDEX(Labor!$D$2:$D$301,MATCH(TEXT($H$3,"yyyy-mm-dd")&"#"&3,Labor!$I$2:$I$301,0)),"") | D12: =IFERROR(INDEX(Labor!$E$2:$E$301,MATCH(TEXT($H$3,"yyyy-mm-dd")&"#"&3,Labor!$I$2:$I$301,0)),"") | E12: =IFERROR(INDEX(Labor!$F$2:$F$301,MATCH(TEXT($H$3,"yyyy-mm-dd")&"#"&3,Labor!$I$2:$I$301,0)),"")
B13: =IFERROR(INDEX(Labor!$C$2:$C$301,MATCH(TEXT($H$3,"yyyy-mm-dd")&"#"&4,Labor!$I$2:$I$301,0)),"") | C13: =IFERROR(INDEX(Labor!$D$2:$D$301,MATCH(TEXT($H$3,"yyyy-mm-dd")&"#"&4,Labor!$I$2:$I$301,0)),"") | D13: =IFERROR(INDEX(Labor!$E$2:$E$301,MATCH(TEXT($H$3,"yyyy-mm-dd")&"#"&4,Labor!$I$2:$I$301,0)),"") | E13: =IFERROR(INDEX(Labor!$F$2:$F$301,MATCH(TEXT($H$3,"yyyy-mm-dd")&"#"&4,Labor!$I$2:$I$301,0)),"")
B14: =IFERROR(INDEX(Labor!$C$2:$C$301,MATCH(TEXT($H$3,"yyyy-mm-dd")&"#"&5,Labor!$I$2:$I$301,0)),"") | C14: =IFERROR(INDEX(Labor!$D$2:$D$301,MATCH(TEXT($H$3,"yyyy-mm-dd")&"#"&5,Labor!$I$2:$I$301,0)),"") | D14: =IFERROR(INDEX(Labor!$E$2:$E$301,MATCH(TEXT($H$3,"yyyy-mm-dd")&"#"&5,Labor!$I$2:$I$301,0)),"") | E14: =IFERROR(INDEX(Labor!$F$2:$F$301,MATCH(TEXT($H$3,"yyyy-mm-dd")&"#"&5,Labor!$I$2:$I$301,0)),"")
B15: =IFERROR(INDEX(Labor!$C$2:$C$301,MATCH(TEXT($H$3,"yyyy-mm-dd")&"#"&6,Labor!$I$2:$I$301,0)),"") | C15: =IFERROR(INDEX(Labor!$D$2:$D$301,MATCH(TEXT($H$3,"yyyy-mm-dd")&"#"&6,Labor!$I$2:$I$301,0)),"") | D15: =IFERROR(INDEX(Labor!$E$2:$E$301,MATCH(TEXT($H$3,"yyyy-mm-dd")&"#"&6,Labor!$I$2:$I$301,0)),"") | E15: =IFERROR(INDEX(Labor!$F$2:$F$301,MATCH(TEXT($H$3,"yyyy-mm-dd")&"#"&6,Labor!$I$2:$I$301,0)),"")
B16: =IFERROR(INDEX(Labor!$C$2:$C$301,MATCH(TEXT($H$3,"yyyy-mm-dd")&"#"&7,Labor!$I$2:$I$301,0)),"") | C16: =IFERROR(INDEX(Labor!$D$2:$D$301,MATCH(TEXT($H$3,"yyyy-mm-dd")&"#"&7,Labor!$I$2:$I$301,0)),"") | D16: =IFERROR(INDEX(Labor!$E$2:$E$301,MATCH(TEXT($H$3,"yyyy-mm-dd")&"#"&7,Labor!$I$2:$I$301,0)),"") | E16: =IFERROR(INDEX(Labor!$F$2:$F$301,MATCH(TEXT($H$3,"yyyy-mm-dd")&"#"&7,Labor!$I$2:$I$301,0)),"")
B17: =IFERROR(INDEX(Labor!$C$2:$C$301,MATCH(TEXT($H$3,"yyyy-mm-dd")&"#"&8,Labor!$I$2:$I$301,0)),"") | C17: =IFERROR(INDEX(Labor!$D$2:$D$301,MATCH(TEXT($H$3,"yyyy-mm-dd")&"#"&8,Labor!$I$2:$I$301,0)),"") | D17: =IFERROR(INDEX(Labor!$E$2:$E$301,MATCH(TEXT($H$3,"yyyy-mm-dd")&"#"&8,Labor!$I$2:$I$301,0)),"") | E17: =IFERROR(INDEX(Labor!$F$2:$F$301,MATCH(TEXT($H$3,"yyyy-mm-dd")&"#"&8,Labor!$I$2:$I$301,0)),"")
B18: =IFERROR(INDEX(Labor!$C$2:$C$301,MATCH(TEXT($H$3,"yyyy-mm-dd")&"#"&9,Labor!$I$2:$I$301,0)),"") | C18: =IFERROR(INDEX(Labor!$D$2:$D$301,MATCH(TEXT($H$3,"yyyy-mm-dd")&"#"&9,Labor!$I$2:$I$301,0)),"") | D18: =IFERROR(INDEX(Labor!$E$2:$E$301,MATCH(TEXT($H$3,"yyyy-mm-dd")&"#"&9,Labor!$I$2:$I$301,0)),"") | E18: =IFERROR(INDEX(Labor!$F$2:$F$301,MATCH(TEXT($H$3,"yyyy-mm-dd")&"#"&9,Labor!$I$2:$I$301,0)),"")
B19: =IFERROR(INDEX(Labor!$C$2:$C$301,MATCH(TEXT($H$3,"yyyy-mm-dd")&"#"&10,Labor!$I$2:$I$301,0)),"") | C19: =IFERROR(INDEX(Labor!$D$2:$D$301,MATCH(TEXT($H$3,"yyyy-mm-dd")&"#"&10,Labor!$I$2:$I$301,0)),"") | D19: =IFERROR(INDEX(Labor!$E$2:$E$301,MATCH(TEXT($H$3,"yyyy-mm-dd")&"#"&10,Labor!$I$2:$I$301,0)),"") | E19: =IFERROR(INDEX(Labor!$F$2:$F$301,MATCH(TEXT($H$3,"yyyy-mm-dd")&"#"&10,Labor!$I$2:$I$301,0)),"")
B20: =IFERROR(INDEX(Labor!$C$2:$C$301,MATCH(TEXT($H$3,"yyyy-mm-dd")&"#"&11,Labor!$I$2:$I$301,0)),"") | C20: =IFERROR(INDEX(Labor!$D$2:$D$301,MATCH(TEXT($H$3,"yyyy-mm-dd")&"#"&11,Labor!$I$2:$I$301,0)),"") | D20: =IFERROR(INDEX(Labor!$E$2:$E$301,MATCH(TEXT($H$3,"yyyy-mm-dd")&"#"&11,Labor!$I$2:$I$301,0)),"") | E20: =IFERROR(INDEX(Labor!$F$2:$F$301,MATCH(TEXT($H$3,"yyyy-mm-dd")&"#"&11,Labor!$I$2:$I$301,0)),"")
B21: =IFERROR(INDEX(Labor!$C$2:$C$301,MATCH(TEXT($H$3,"yyyy-mm-dd")&"#"&12,Labor!$I$2:$I$301,0)),"") | C21: =IFERROR(INDEX(Labor!$D$2:$D$301,MATCH(TEXT($H$3,"yyyy-mm-dd")&"#"&12,Labor!$I$2:$I$301,0)),"") | D21: =IFERROR(INDEX(Labor!$E$2:$E$301,MATCH(TEXT($H$3,"yyyy-mm-dd")&"#"&12,Labor!$I$2:$I$301,0)),"") | E21: =IFERROR(INDEX(Labor!$F$2:$F$301,MATCH(TEXT($H$3,"yyyy-mm-dd")&"#"&12,Labor!$I$2:$I$301,0)),"")
D22: Labor total | E22: =CEILING(SUM(E10:E21),RoundInc)
A24: Charges | B24: Category | C24: Item / Description | D24: Qty | E24: Rate | F24: Amount
B25: =IFERROR(INDEX(Charges!$C$2:$C$301,MATCH(TEXT($H$3,"yyyy-mm-dd")&"#"&1,Charges!$N$2:$N$301,0)),"") | C25: =IFERROR(INDEX(Charges!$E$2:$E$301,MATCH(TEXT($H$3,"yyyy-mm-dd")&"#"&1,Charges!$N$2:$N$301,0)),"") | D25: =IFERROR(INDEX(Charges!$F$2:$F$301,MATCH(TEXT($H$3,"yyyy-mm-dd")&"#"&1,Charges!$N$2:$N$301,0)),"") | E25: =IFERROR(INDEX(Charges!$H$2:$H$301,MATCH(TEXT($H$3,"yyyy-mm-dd")&"#"&1,Charges!$N$2:$N$301,0)),"") | F25: =IFERROR(INDEX(Charges!$I$2:$I$301,MATCH(TEXT($H$3,"yyyy-mm-dd")&"#"&1,Charges!$N$2:$N$301,0)),"")
B26: =IFERROR(INDEX(Charges!$C$2:$C$301,MATCH(TEXT($H$3,"yyyy-mm-dd")&"#"&2,Charges!$N$2:$N$301,0)),"") | C26: =IFERROR(INDEX(Charges!$E$2:$E$301,MATCH(TEXT($H$3,"yyyy-mm-dd")&"#"&2,Charges!$N$2:$N$301,0)),"") | D26: =IFERROR(INDEX(Charges!$F$2:$F$301,MATCH(TEXT($H$3,"yyyy-mm-dd")&"#"&2,Charges!$N$2:$N$301,0)),"") | E26: =IFERROR(INDEX(Charges!$H$2:$H$301,MATCH(TEXT($H$3,"yyyy-mm-dd")&"#"&2,Charges!$N$2:$N$301,0)),"") | F26: =IFERROR(INDEX(Charges!$I$2:$I$301,MATCH(TEXT($H$3,"yyyy-mm-dd")&"#"&2,Charges!$N$2:$N$301,0)),"")
B27: =IFERROR(INDEX(Charges!$C$2:$C$301,MATCH(TEXT($H$3,"yyyy-mm-dd")&"#"&3,Charges!$N$2:$N$301,0)),"") | C27: =IFERROR(INDEX(Charges!$E$2:$E$301,MATCH(TEXT($H$3,"yyyy-mm-dd")&"#"&3,Charges!$N$2:$N$301,0)),"") | D27: =IFERROR(INDEX(Charges!$F$2:$F$301,MATCH(TEXT($H$3,"yyyy-mm-dd")&"#"&3,Charges!$N$2:$N$301,0)),"") | E27: =IFERROR(INDEX(Charges!$H$2:$H$301,MATCH(TEXT($H$3,"yyyy-mm-dd")&"#"&3,Charges!$N$2:$N$301,0)),"") | F27: =IFERROR(INDEX(Charges!$I$2:$I$301,MATCH(TEXT($H$3,"yyyy-mm-dd")&"#"&3,Charges!$N$2:$N$301,0)),"")
B28: =IFERROR(INDEX(Charges!$C$2:$C$301,MATCH(TEXT($H$3,"yyyy-mm-dd")&"#"&4,Charges!$N$2:$N$301,0)),"") | C28: =IFERROR(INDEX(Charges!$E$2:$E$301,MATCH(TEXT($H$3,"yyyy-mm-dd")&"#"&4,Charges!$N$2:$N$301,0)),"") | D28: =IFERROR(INDEX(Charges!$F$2:$F$301,MATCH(TEXT($H$3,"yyyy-mm-dd")&"#"&4,Charges!$N$2:$N$301,0)),"") | E28: =IFERROR(INDEX(Charges!$H$2:$H$301,MATCH(TEXT($H$3,"yyyy-mm-dd")&"#"&4,Charges!$N$2:$N$301,0)),"") | F28: =IFERROR(INDEX(Charges!$I$2:$I$301,MATCH(TEXT($H$3,"yyyy-mm-dd")&"#"&4,Charges!$N$2:$N$301,0)),"")
B29: =IFERROR(INDEX(Charges!$C$2:$C$301,MATCH(TEXT($H$3,"yyyy-mm-dd")&"#"&5,Charges!$N$2:$N$301,0)),"") | C29: =IFERROR(INDEX(Charges!$E$2:$E$301,MATCH(TEXT($H$3,"yyyy-mm-dd")&"#"&5,Charges!$N$2:$N$301,0)),"") | D29: =IFERROR(INDEX(Charges!$F$2:$F$301,MATCH(TEXT($H$3,"yyyy-mm-dd")&"#"&5,Charges!$N$2:$N$301,0)),"") | E29: =IFERROR(INDEX(Charges!$H$2:$H$301,MATCH(TEXT($H$3,"yyyy-mm-dd")&"#"&5,Charges!$N$2:$N$301,0)),"") | F29: =IFERROR(INDEX(Charges!$I$2:$I$301,MATCH(TEXT($H$3,"yyyy-mm-dd")&"#"&5,Charges!$N$2:$N$301,0)),"")
B30: =IFERROR(INDEX(Charges!$C$2:$C$301,MATCH(TEXT($H$3,"yyyy-mm-dd")&"#"&6,Charges!$N$2:$N$301,0)),"") | C30: =IFERROR(INDEX(Charges!$E$2:$E$301,MATCH(TEXT($H$3,"yyyy-mm-dd")&"#"&6,Charges!$N$2:$N$301,0)),"") | D30: =IFERROR(INDEX(Charges!$F$2:$F$301,MATCH(TEXT($H$3,"yyyy-mm-dd")&"#"&6,Charges!$N$2:$N$301,0)),"") | E30: =IFERROR(INDEX(Charges!$H$2:$H$301,MATCH(TEXT($H$3,"yyyy-mm-dd")&"#"&6,Charges!$N$2:$N$301,0)),"") | F30: =IFERROR(INDEX(Charges!$I$2:$I$301,MATCH(TEXT($H$3,"yyyy-mm-dd")&"#"&6,Charges!$N$2:$N$301,0)),"")
B31: =IFERROR(INDEX(Charges!$C$2:$C$301,MATCH(TEXT($H$3,"yyyy-mm-dd")&"#"&7,Charges!$N$2:$N$301,0)),"") | C31: =IFERROR(INDEX(Charges!$E$2:$E$301,MATCH(TEXT($H$3,"yyyy-mm-dd")&"#"&7,Charges!$N$2:$N$301,0)),"") | D31: =IFERROR(INDEX(Charges!$F$2:$F$301,MATCH(TEXT($H$3,"yyyy-mm-dd")&"#"&7,Charges!$N$2:$N$301,0)),"") | E31: =IFERROR(INDEX(Charges!$H$2:$H$301,MATCH(TEXT($H$3,"yyyy-mm-dd")&"#"&7,Charges!$N$2:$N$301,0)),"") | F31: =IFERROR(INDEX(Charges!$I$2:$I$301,MATCH(TEXT($H$3,"yyyy-mm-dd")&"#"&7,Charges!$N$2:$N$301,0)),"")
B32: =IFERROR(INDEX(Charges!$C$2:$C$301,MATCH(TEXT($H$3,"yyyy-mm-dd")&"#"&8,Charges!$N$2:$N$301,0)),"") | C32: =IFERROR(INDEX(Charges!$E$2:$E$301,MATCH(TEXT($H$3,"yyyy-mm-dd")&"#"&8,Charges!$N$2:$N$301,0)),"") | D32: =IFERROR(INDEX(Charges!$F$2:$F$301,MATCH(TEXT($H$3,"yyyy-mm-dd")&"#"&8,Charges!$N$2:$N$301,0)),"") | E32: =IFERROR(INDEX(Charges!$H$2:$H$301,MATCH(TEXT($H$3,"yyyy-mm-dd")&"#"&8,Charges!$N$2:$N$301,0)),"") | F32: =IFERROR(INDEX(Charges!$I$2:$I$301,MATCH(TEXT($H$3,"yyyy-mm-dd")&"#"&8,Charges!$N$2:$N$301,0)),"")
B33: =IFERROR(INDEX(Charges!$C$2:$C$301,MATCH(TEXT($H$3,"yyyy-mm-dd")&"#"&9,Charges!$N$2:$N$301,0)),"") | C33: =IFERROR(INDEX(Charges!$E$2:$E$301,MATCH(TEXT($H$3,"yyyy-mm-dd")&"#"&9,Charges!$N$2:$N$301,0)),"") | D33: =IFERROR(INDEX(Charges!$F$2:$F$301,MATCH(TEXT($H$3,"yyyy-mm-dd")&"#"&9,Charges!$N$2:$N$301,0)),"") | E33: =IFERROR(INDEX(Charges!$H$2:$H$301,MATCH(TEXT($H$3,"yyyy-mm-dd")&"#"&9,Charges!$N$2:$N$301,0)),"") | F33: =IFERROR(INDEX(Charges!$I$2:$I$301,MATCH(TEXT($H$3,"yyyy-mm-dd")&"#"&9,Charges!$N$2:$N$301,0)),"")
B34: =IFERROR(INDEX(Charges!$C$2:$C$301,MATCH(TEXT($H$3,"yyyy-mm-dd")&"#"&10,Charges!$N$2:$N$301,0)),"") | C34: =IFERROR(INDEX(Charges!$E$2:$E$301,MATCH(TEXT($H$3,"yyyy-mm-dd")&"#"&10,Charges!$N$2:$N$301,0)),"") | D34: =IFERROR(INDEX(Charges!$F$2:$F$301,MATCH(TEXT($H$3,"yyyy-mm-dd")&"#"&10,Charges!$N$2:$N$301,0)),"") | E34: =IFERROR(INDEX(Charges!$H$2:$H$301,MATCH(TEXT($H$3,"yyyy-mm-dd")&"#"&10,Charges!$N$2:$N$301,0)),"") | F34: =IFERROR(INDEX(Charges!$I$2:$I$301,MATCH(TEXT($H$3,"yyyy-mm-dd")&"#"&10,Charges!$N$2:$N$301,0)),"")
B35: =IFERROR(INDEX(Charges!$C$2:$C$301,MATCH(TEXT($H$3,"yyyy-mm-dd")&"#"&11,Charges!$N$2:$N$301,0)),"") | C35: =IFERROR(INDEX(Charges!$E$2:$E$301,MATCH(TEXT($H$3,"yyyy-mm-dd")&"#"&11,Charges!$N$2:$N$301,0)),"") | D35: =IFERROR(INDEX(Charges!$F$2:$F$301,MATCH(TEXT($H$3,"yyyy-mm-dd")&"#"&11,Charges!$N$2:$N$301,0)),"") | E35: =IFERROR(INDEX(Charges!$H$2:$H$301,MATCH(TEXT($H$3,"yyyy-mm-dd")&"#"&11,Charges!$N$2:$N$301,0)),"") | F35: =IFERROR(INDEX(Charges!$I$2:$I$301,MATCH(TEXT($H$3,"yyyy-mm-dd")&"#"&11,Charges!$N$2:$N$301,0)),"")
B36: =IFERROR(INDEX(Charges!$C$2:$C$301,MATCH(TEXT($H$3,"yyyy-mm-dd")&"#"&12,Charges!$N$2:$N$301,0)),"") | C36: =IFERROR(INDEX(Charges!$E$2:$E$301,MATCH(TEXT($H$3,"yyyy-mm-dd")&"#"&12,Charges!$N$2:$N$301,0)),"") | D36: =IFERROR(INDEX(Charges!$F$2:$F$301,MATCH(TEXT($H$3,"yyyy-mm-dd")&"#"&12,Charges!$N$2:$N$301,0)),"") | E36: =IFERROR(INDEX(Charges!$H$2:$H$301,MATCH(TEXT($H$3,"yyyy-mm-dd")&"#"&12,Charges!$N$2:$N$301,0)),"") | F36: =IFERROR(INDEX(Charges!$I$2:$I$301,MATCH(TEXT($H$3,"yyyy-mm-dd")&"#"&12,Charges!$N$2:$N$301,0)),"")
D37: Truck / trip charges | F37: =CEILING(SUMIFS(Charges!$I$2:$I$301,Charges!$C$2:$C$301,"Truck 1",Charges!$J$2:$J$301,"Yes",Charges!$A$2:$A$301,$H$3)+SUMIFS(Charges!$I$2:$I$301,Charges!$C$2:$C$301,"Truck 2",Charges!$J$2:$J$301,"Yes",Charges!$A$2:$A$301,$H$3)+SUMIFS(Charges!$I$2:$I$301,Charges!$C$2:$C$301,"Trip charge",Charges!$J$2:$J$301,"Yes",Charges!$A$2:$A$301,$H$3),RoundInc)
D38: Equipment | F38: =CEILING(SUMIFS(Charges!$I$2:$I$301,Charges!$C$2:$C$301,"Equipment",Charges!$J$2:$J$301,"Yes",Charges!$A$2:$A$301,$H$3),RoundInc)
D39: Expenses (before upcharge) | F39: =CEILING(SUMIFS(Charges!$I$2:$I$301,Charges!$K$2:$K$301,"Yes",Charges!$J$2:$J$301,"Yes",Charges!$A$2:$A$301,$H$3),RoundInc)
D40: Expense upcharge 15% | F40: =CEILING(F39*UpchargePct,RoundInc)
D41: Charges total | F41: =CEILING(F37+F38+F39+F40,RoundInc)
D43: DAY TOTAL | F43: =CEILING(E22+F41,RoundInc)

Sheet Notes
A1: Notes — cómo mantener este libro
A4: Flujo diario | B4: Rellena Labor (horas por técnico y día) y Charges (camiones, trip charges, truck stock, compras, equipos, gastos). No hace falta crear nada nuevo: el libro es acumulativo.
A5: Factura | B5: En Invoice elige Client y el rango From/To. Los bloques de trabajo, camiones/equipos y gastos se calculan con SUMIFS sobre el rango.
A6: Nómina | B6: En Payroll elige From/To: horas del rango por técnico × su tarifa a pagar, más los gastos marcados "Reimburse tech" = Yes.
A7: Hoja diaria | B7: DailySheet imprime el detalle de un día concreto (la fecha sale de Invoice!B5). Puedes cambiarla en H3 para revisar otro día.
A8: SUMIFS | B8: SUMIFS(Charge, Category, "Truck 1", Billable, "Yes", Date, ">="&From, Date, "<="&To). Se usa SUMIFS en vez de SUM porque filtra por varias condiciones a la vez.
A9: Redondeo | B9: Todo importe pasa por CEILING(x, RoundInc) con RoundInc = 0,01 en Setup. Si quieres redondear al dólar, pon 1 en Setup!B6.
A10: Recargo del 15% | B10: La columna "Markup 15%" de Charges marca solas las categorías Truck stock, Purchase, Tech expense y Other. Para añadir otra categoría con recargo, añádela a la lista de Setup y ajusta la fórmula de la columna K de Charges.
A11: Rate automática | B11: La columna Rate de Charges busca en el catálogo de camiones y equipos. Si escribes un importe en "Amount (override)", ese importe manda sobre el catálogo (para compras y trip charges).
A12: Añadir filas | B12: Las fórmulas cubren hasta la fila 301. Si necesitas más, arrastra la última fila hacia abajo: los SUMIFS de Invoice/Payroll cubren el mismo rango.
A13: Añadir técnicos | B13: Añade el técnico en Setup (filas 30-37) y amplía los bloques de Invoice/Payroll copiando una fila existente.
A14: Equipos | B14: Añade equipos al catálogo de Setup (filas 16-25) con su tarifa de día completo y de medio día.
A15: Imprimir | B15: Invoice, Payroll y DailySheet ya están configuradas en A4 vertical a una página de ancho. "Guardar como PDF" en Excel usa esa configuración.
A16: Compatibilidad | B16: Todo funciona en Excel 2013: no se usan XLOOKUP, LET, LAMBDA, TEXTJOIN, MAXIFS ni fórmulas matriciales.
